[2024-05-30T11:36:57.943+0000] {local_task_job_runner.py:120} INFO - ::group::Pre task execution logs
[2024-05-30T11:36:57.982+0000] {taskinstance.py:2076} INFO - Dependencies all met for dep_context=non-requeueable deps ti=<TaskInstance: extenso_assignment.output manual__2024-05-30T11:36:52.854299+00:00 [queued]>
[2024-05-30T11:36:57.990+0000] {taskinstance.py:2076} INFO - Dependencies all met for dep_context=requeueable deps ti=<TaskInstance: extenso_assignment.output manual__2024-05-30T11:36:52.854299+00:00 [queued]>
[2024-05-30T11:36:57.991+0000] {taskinstance.py:2306} INFO - Starting attempt 1 of 1
[2024-05-30T11:36:58.007+0000] {taskinstance.py:2330} INFO - Executing <Task(PythonOperator): output> on 2024-05-30 11:36:52.854299+00:00
[2024-05-30T11:36:58.020+0000] {standard_task_runner.py:90} INFO - Running: ['***', 'tasks', 'run', 'extenso_assignment', 'output', 'manual__2024-05-30T11:36:52.854299+00:00', '--job-id', '17', '--raw', '--subdir', 'DAGS_FOLDER/dump_load_dag.py', '--cfg-path', '/tmp/tmp_5i_3e2u']
[2024-05-30T11:36:58.023+0000] {standard_task_runner.py:91} INFO - Job 17: Subtask output
[2024-05-30T11:36:58.026+0000] {logging_mixin.py:188} WARNING - /home/***/.local/lib/python3.12/site-packages/***/task/task_runner/standard_task_runner.py:61 DeprecationWarning: This process (pid=413) is multi-threaded, use of fork() may lead to deadlocks in the child.
[2024-05-30T11:36:58.027+0000] {standard_task_runner.py:63} INFO - Started process 423 to run task
[2024-05-30T11:36:58.076+0000] {task_command.py:426} INFO - Running <TaskInstance: extenso_assignment.output manual__2024-05-30T11:36:52.854299+00:00 [running]> on host d78d325bbf3e
[2024-05-30T11:36:58.200+0000] {taskinstance.py:2648} INFO - Exporting env vars: AIRFLOW_CTX_DAG_OWNER='***' AIRFLOW_CTX_DAG_ID='extenso_assignment' AIRFLOW_CTX_TASK_ID='output' AIRFLOW_CTX_EXECUTION_DATE='2024-05-30T11:36:52.854299+00:00' AIRFLOW_CTX_TRY_NUMBER='1' AIRFLOW_CTX_DAG_RUN_ID='manual__2024-05-30T11:36:52.854299+00:00'
[2024-05-30T11:36:58.203+0000] {taskinstance.py:430} INFO - ::endgroup::
[2024-05-30T11:36:58.278+0000] {logging_mixin.py:188} WARNING - /opt/***/dags/Load_DF.py:6 FutureWarning: DataFrame.applymap has been deprecated. Use DataFrame.map instead.
[2024-05-30T11:36:58.289+0000] {logging_mixin.py:188} WARNING - /opt/***/dags/Load_DF.py:6 FutureWarning: DataFrame.applymap has been deprecated. Use DataFrame.map instead.
[2024-05-30T11:36:58.296+0000] {logging_mixin.py:188} WARNING - /opt/***/dags/Load_DF.py:6 FutureWarning: DataFrame.applymap has been deprecated. Use DataFrame.map instead.
[2024-05-30T11:36:58.303+0000] {logging_mixin.py:188} WARNING - /opt/***/dags/Load_DF.py:6 FutureWarning: DataFrame.applymap has been deprecated. Use DataFrame.map instead.
[2024-05-30T11:36:58.310+0000] {logging_mixin.py:188} WARNING - /opt/***/dags/Load_DF.py:6 FutureWarning: DataFrame.applymap has been deprecated. Use DataFrame.map instead.
[2024-05-30T11:36:58.316+0000] {logging_mixin.py:188} WARNING - /opt/***/dags/Load_DF.py:6 FutureWarning: DataFrame.applymap has been deprecated. Use DataFrame.map instead.
[2024-05-30T11:36:58.666+0000] {taskinstance.py:441} INFO - ::group::Post task execution logs
[2024-05-30T11:36:58.668+0000] {taskinstance.py:2905} ERROR - Task failed with exception
Traceback (most recent call last):
  File "/home/airflow/.local/lib/python3.12/site-packages/airflow/models/taskinstance.py", line 465, in _execute_task
    result = _execute_callable(context=context, **execute_callable_kwargs)
             ^^^^^^^^^^^^^^^^^^^^^^^^^^^^^^^^^^^^^^^^^^^^^^^^^^^^^^^^^^^^^
  File "/home/airflow/.local/lib/python3.12/site-packages/airflow/models/taskinstance.py", line 432, in _execute_callable
    return execute_callable(context=context, **execute_callable_kwargs)
           ^^^^^^^^^^^^^^^^^^^^^^^^^^^^^^^^^^^^^^^^^^^^^^^^^^^^^^^^^^^^
  File "/home/airflow/.local/lib/python3.12/site-packages/airflow/models/baseoperator.py", line 400, in wrapper
    return func(self, *args, **kwargs)
           ^^^^^^^^^^^^^^^^^^^^^^^^^^^
  File "/home/airflow/.local/lib/python3.12/site-packages/airflow/operators/python.py", line 235, in execute
    return_value = self.execute_callable()
                   ^^^^^^^^^^^^^^^^^^^^^^^
  File "/home/airflow/.local/lib/python3.12/site-packages/airflow/operators/python.py", line 252, in execute_callable
    return self.python_callable(*self.op_args, **self.op_kwargs)
           ^^^^^^^^^^^^^^^^^^^^^^^^^^^^^^^^^^^^^^^^^^^^^^^^^^^^^
  File "/opt/airflow/dags/preprocess_combination.py", line 76, in final_entity_matching
    return save_layouts(layouts,'/opt/airflow/files/output_files/final_output.csv')
           ^^^^^^^^^^^^^^^^^^^^^^^^^^^^^^^^^^^^^^^^^^^^^^^^^^^^^^^^^^^^^^^^^^^^^^^^
  File "/opt/airflow/dags/preprocess_combination.py", line 73, in save_layouts
    final_df.to_csv(final_result_path, index=False)
  File "/home/airflow/.local/lib/python3.12/site-packages/pandas/util/_decorators.py", line 333, in wrapper
    return func(*args, **kwargs)
           ^^^^^^^^^^^^^^^^^^^^^
  File "/home/airflow/.local/lib/python3.12/site-packages/pandas/core/generic.py", line 3967, in to_csv
    return DataFrameRenderer(formatter).to_csv(
           ^^^^^^^^^^^^^^^^^^^^^^^^^^^^^^^^^^^^
  File "/home/airflow/.local/lib/python3.12/site-packages/pandas/io/formats/format.py", line 1014, in to_csv
    csv_formatter.save()
  File "/home/airflow/.local/lib/python3.12/site-packages/pandas/io/formats/csvs.py", line 251, in save
    with get_handle(
         ^^^^^^^^^^^
  File "/home/airflow/.local/lib/python3.12/site-packages/pandas/io/common.py", line 749, in get_handle
    check_parent_directory(str(handle))
  File "/home/airflow/.local/lib/python3.12/site-packages/pandas/io/common.py", line 616, in check_parent_directory
    raise OSError(rf"Cannot save file into a non-existent directory: '{parent}'")
OSError: Cannot save file into a non-existent directory: '/opt/***/files/output_files/final_output.csv'
[2024-05-30T11:36:58.707+0000] {taskinstance.py:1206} INFO - Marking task as FAILED. dag_id=extenso_assignment, task_id=output, run_id=manual__2024-05-30T11:36:52.854299+00:00, execution_date=20240530T113652, start_date=20240530T113657, end_date=20240530T113658
[2024-05-30T11:36:58.719+0000] {standard_task_runner.py:110} ERROR - Failed to execute job 17 for task output (Cannot save file into a non-existent directory: '/opt/***/files/output_files/final_output.csv'; 423)
[2024-05-30T11:36:58.764+0000] {local_task_job_runner.py:240} INFO - Task exited with return code 1
[2024-05-30T11:36:58.782+0000] {taskinstance.py:3498} INFO - 0 downstream tasks scheduled from follow-on schedule check
[2024-05-30T11:36:58.784+0000] {local_task_job_runner.py:222} INFO - ::endgroup::
